Workbook

Sheet Dashboard
A1: MCAA — BLIGNAUTSRUS NORTH COMMUNITY ASSOCIATION
A2: Financial & Membership Dashboard | April 2026
A5: 📋 NAVIGATE TO TABS | B5: Tab Name | C5: Description
B6: Comprehensive list | C6: Master member database — all 533 entries including owner/tenant details, plot numbers, street addresses, debit order refs, and 13 months of payment history.
B7: Bank Statement Mar-26 | C7: Full April 2026 Capitec bank statement with every transaction categorised, matched to members, and flagged with confidence level.
B8: Reconciliation Mar-26 | C8: Month-end reconciliation summary — money in vs. money out, opening/closing balances, and per-member EFT & camera payment matching with differences.
B9: Expense Register | C9: Itemised list of all April 2026 outflows: salary, maintenance, camera purchase, utilities, bank fees, and reversals (R 36 792 total).
B10: Payment Summary | C10: Yearly membership payment overview — monthly collection totals (Apr 2025–Mar 2026), paying vs. non-paying member counts, and total revenue to date.
B11: Members Report | C11: Individual member payment detail report — total paid per member across the year, with non-payers highlighted in red.
B12: Matching Audit Log | C12: Full audit trail of every bank transaction matched to a member — method used (D/O batch, plot-street, name fuzzy), confidence level, and row reference.
B13: Street Captains | C13: Street captain directory — name, email, phone, and paying-member ratio per street (e.g. '4 of 8 paying on Blignaut Street').
B14: Blignautsrus North | C14: Plot-level master register for the Blignautsrus North area — owner/tenant, contacts, D/O reference, and full monthly payment columns.
B15: Notes | C15: Operational notes — Mercantile debit order system login instructions, Capitec support number, and useful reference links.
A17: 💰 MARCH 2026 FINANCIAL SNAPSHOT
B18: Money In (Mar) | D18: Money Out (Mar) | F18: Net (Mar) | H18: Closing Balance | J18: Recon Difference
B19: ='Bank Reconciliation'!D10 -> 60875 | D19: ='Bank Reconciliation'!D20 -> 36792 | F19: ='Bank Reconciliation'!D10-'Bank Reconciliation'!D20 -> 24083 | H19: ='Bank Reconciliation'!D27 -> 42267.9 | J19: ='Bank Reconciliation'!D28 -> -26
B20: DO + EFT + Camera | D20: Salary, maint., cameras, fees | F20: In minus Out | H20: Actual per bank statement | J20: Calculated vs Actual
A22: 📅 MONTHLY COLLECTIONS (Apr 2025 – Mar 2026) | H22: 👥 MEMBERSHIP STATS
B23: Month | C23: Collected (R) | D23: # Payers | E23: Avg / Payer (R) | H23: Metric | J23: Value
B24: 46137 | C24: ='Payment Summary'!C22 -> 26778 | D24: ='Payment Summary'!D22 -> 79 | E24: =IF(D24>0,C24/D24,0) -> 338.96203 | H24: Total Members on List | J24: ='Payment Summary'!D7 -> 533
B25: 46167 | C25: ='Payment Summary'!C23 -> 25841 | D25: ='Payment Summary'!D23 -> 78 | E25: =IF(D25>0,C25/D25,0) -> 331.29487 | H25: Paying Members | J25: ='Payment Summary'!D8 -> 132
B26: 46198 | C26: ='Payment Summary'!C24 -> 25108 | D26: ='Payment Summary'!D24 -> 74 | E26: =IF(D26>0,C26/D26,0) -> 339.2973 | H26: Non-Paying Members | J26: ='Payment Summary'!D9 -> 401
B27: 46228 | C27: ='Payment Summary'!C25 -> 24028 | D27: ='Payment Summary'!D25 -> 70 | E27: =IF(D27>0,C27/D27,0) -> 343.25714 | H27: Payment Rate | J27: ='Payment Summary'!D16 -> 0.25
B28: 46259 | C28: ='Payment Summary'!C26 -> 30233 | D28: ='Payment Summary'!D26 -> 71 | E28: =IF(D28>0,C28/D28,0) -> 425.8169 | H28: Unique Plot Numbers | J28: ='Payment Summary'!D11 -> 184
B29: 46290 | C29: ='Payment Summary'!C27 -> 26733 | D29: ='Payment Summary'!D27 -> 68 | E29: =IF(D29>0,C29/D29,0) -> 393.13235 | H29: Plots w/ Multiple Entries | J29: ='Payment Summary'!D12 -> 118
B30: 46320 | C30: ='Payment Summary'!C28 -> 24183 | D30: ='Payment Summary'!D28 -> 70 | E30: =IF(D30>0,C30/D30,0) -> 345.47143 | H30: Total Revenue (Year) | J30: ='Payment Summary'!D14 -> 372684
B31: 46351 | C31: ='Payment Summary'!C29 -> 21583 | D31: ='Payment Summary'!D29 -> 64 | E31: =IF(D31>0,C31/D31,0) -> 337.23438
B32: 46381 | C32: ='Payment Summary'!C30 -> 22883 | D32: ='Payment Summary'!D30 -> 66 | E32: =IF(D32>0,C32/D32,0) -> 346.71212
B33: 46048 | C33: ='Payment Summary'!C31 -> 24233 | D33: ='Payment Summary'!D31 -> 69 | E33: =IF(D33>0,C33/D33,0) -> 351.2029
B34: 46079 | C34: ='Payment Summary'!C32 -> 32833 | D34: ='Payment Summary'!D32 -> 66 | E34: =IF(D34>0,C34/D34,0) -> 497.4697
B35: Mar-26 (prev) | C35: ='Payment Summary'!C33 -> 27373 | D35: ='Payment Summary'!D33 -> 75 | E35: =IF(D35>0,C35/D35,0) -> 364.97333
B36: Mar-26 ★ | C36: ='Payment Summary'!C34 -> 60875 | D36: ='Payment Summary'!D34 -> 101 | E36: =IF(D36>0,C36/D36,0) -> 602.72277
B37: TOTAL | C37: ='Payment Summary'!D14 -> 372684
A41: 📄 MARCH 2026 EXPENSE BREAKDOWN | H41: 🏥 STREET CAPTAINS — COLLECTION RATE
B42: Category | C42: Amount (R) | D42: % of Total | E42: Notes | H42: Street | I42: Captain | J42: Paying | K42: of Total | L42: Rate
B43: ='Expense Register'!C2 -> Bank fee | C43: ='Expense Register'!D2 -> 414.98 | D43: =C43/'Expense Register'!D12 -> 0.011279082 | E43: ='Expense Register'!E2 -> DO service charge | H43: Blignaut Street | I43: (vacant) | J43: 4 | K43: 8 | L43: =J43/K43 -> 0.5
B44: ='Expense Register'!C3 -> Expense | C44: ='Expense Register'!D3 -> 4000 | D44: =C44/'Expense Register'!D12 -> 0.10871929 | E44: ='Expense Register'!E3 -> JLK MCAA | H44: De Wet Street | I44: Richard Bentheim | J44: 7 | K44: 17 | L44: =J44/K44 -> 0.41176471
B45: ='Expense Register'!C4 -> Utilities | C45: ='Expense Register'!D4 -> 471.51 | D45: =C45/'Expense Register'!D12 -> 0.012815558 | E45: ='Expense Register'!E4 -> Water — MR SN LANGA | H45: Eloff Street | I45: (vacant) | J45: 7 | K45: 19 | L45: =J45/K45 -> 0.36842105
B46: ='Expense Register'!C5 -> Reversal | C46: ='Expense Register'!D5 -> 200 | D46: =C46/'Expense Register'!D12 -> 0.0054359643 | E46: ='Expense Register'!E5 -> Unpaid DO reversal | H46: Eeufees Street | I46: Rolf | J46: 2 | K46: 11 | L46: =J46/K46 -> 0.18181818
B47: ='Expense Register'!C6 -> Salary | C47: ='Expense Register'!D6 -> 12500 | D47: =C47/'Expense Register'!D12 -> 0.33974777 | E47: ='Expense Register'!E6 -> Monthly salary — Mengo Sibanda | H47: Fifth Street | I47: Thulani Timile | J47: 5 | K47: 21 | L47: =J47/K47 -> 0.23809524
...

Sheet Comprehensive list
A1: Owner / Tenant | B1: Address | C1: D/O Ref | D1: Plot | E1: Contact 1 | F1: Contact 2 | G1: Contact 3 | H1: E-mail address | I1: Mar-25 DO | J1: Mar-25 EFT | K1: Apr-25 DO | L1: Apr-25 EFT | M1: May-25 DO | N1: May-25 EFT | O1: Jun-25 DO | P1: Jun-25 EFT | Q1: Jul-25 DO | R1: Jul-25 EFT | S1: Aug-25 DO | T1: Aug-25 EFT | U1: Sep-25 DO | V1: Sep-25 EFT | W1: Oct-25 DO | X1: Oct-25 EFT | Y1: Nov-25 DO | Z1: Nov-25 EFT | AA1: Dec-25 DO | AB1: Dec-25 EFT | AC1: Jan-26 DO | AD1: Jan-26 EFT | AE1: Feb-26 DO | AF1: Feb-26 EFT | AG1: Mar-26 DO | AH1: Mar-26 EFT | AI1: Apr-26 DO | AJ1: Apr-26 EFT | AK1: May-26 DO | AL1: May-26 EFT | AM1: Comments | AN1: Camera Payment
A2: Jason Batalides | B2: Blignaut Street | C2: HZB038 | D2: 1 | E2: 082 557 1110 | F2: 0614960119 | I2: 350 | K2: 350 | M2: 350 | O2: 350 | Q2: 350 | S2: 350 | U2: 350 | W2: 350 | Y2: 350 | AA2: 350 | AC2: 350 | AE2: 350 | AG2: 350 | AI2: 350 | AK2: 350 | AO2: 1
A3: Thom Khosa | B3: Hillside Road | D3: 1 | E3: 061 916 3908 | H3: thom.khosa@yahoo.com
A4: S.Potgieter | B4: Hillside Road | D4: 2 | E4: 084 579 0242 | H4: potgieter.steve@gmail.com
A5: Emmanual | B5: Hillside Road | D5: 2 | E5: 063 533 7777
A6: Sim Mdab | B6: Centre Road | D6: 3 | E6: 067 699 2598
A7: Thom Khosa? | B7: Hillside Road | D7: 3
A8: Graham and Alison Webster | B8: Hillside Road | C8: GLV 04 | D8: 4 | E8: 074 245 5446 | F8: 081 589 2689 | H8: grahamw@mweb.co.za | I8: 363 | K8: 363 | M8: 363 | O8: 363 | Q8: 363 | S8: 363 | U8: 363 | W8: 363 | Y8: 363 | AA8: 363 | AC8: 363 | AE8: 363 | AG8: 363 | AI8: 363 | AK8: 363 | AO8: 1
A9: Rowan De Viliers | B9: Hillside Road | D9: 4 | E9: 084 626 2755
A10: Dom Jacob | B10: Hillside Road | D10: 4 | E10: 074 245 5446
A11: John | B11: Hillside Road | D11: 5 | E11: 083 729 6349
A12: Karen | B12: Hillside Road | D12: 5 | E12: 083 575 4241
A13: Beverley Stevens-King | B13: Hillside Road | D13: 5 | E13: 068 150 0714 | F13: -
A14: Phumzile Bango | B14: Hillside Road | D14: 5 | E14: 073 221 5934 | H14: phumzile.bango81@gmail.com
A15: Nkosana Ngobese | B15: Hillside Road | D15: 5 | E15: 083 696 9618
A16: Sefore Pitso-Setere | B16: Hugenote Street | D16: 5 | E16: 076 766 6111 | H16: pitsosetere@yahoo.com
A17: Jonathan | B17: Main Street | D17: 5 | E17: 064 507 3761 | H17: jonathan@614.gmail.com
A18: VACANT | B18: Hillside Road | D18: 6
A19: Matthew | B19: Hillside Road | D19: 7 | E19: 062 896 7659
A20: Eugene | B20: Hugenote Street | D20: 7 | E20: 076 440 9248
A21: Desire (Girls on the Move) | B21: Blignaut Street | D21: 8 | E21: 011 490 0993 | H21: desire@girlsonthemove.co.za
A22: Sibosisu Kheswa | B22: Golf Course Road | D22: 8 | E22: 078 253 3008
A23: Robin Dryburgh | B23: Hillside Road | C23: ANNUAL EFT | D23: 8 | E23: 072 646 0512 | F23: 076 442 0330 | H23: robin@quosano.co.za | T23: 4000 | AM23: SIGNED - ANNUAL PAYMENT Aug25 | AO23: 1
A24: Miroslaw Benpkavic | B24: Danie Theron | C24: ANNUAL EFT | D24: 9 | E24: 082 452 1439 | H24: rupius@easywebmail.co.za | R24: 6000 | AH24: =6000+3500 -> 9500 | AM24: Cameras | AN24: 3500 | AO24: 1 | AP24: 3500
A25: Ian Long | B25: Blignaut Street | C25: BLG010 | D25: 10 | E25: 072 157 9623 | I25: 350 | K25: 350 | M25: 350 | O25: 350 | Q25: 350 | S25: 350 | U25: 350 | W25: 350 | Y25: 350 | AA25: 350 | AC25: 350 | AE25: 350 | AG25: 350 | AI25: 350 | AK25: 350 | AN25: 2000 | AO25: 1
A26: Heinrich Hendrikz | B26: Danie Theron | D26: 10 | E26: 081 016 2982 | H26: heinrichhendrikz@gmail.com | AH26: 500 | AM26: Cameras | AP26: 500
A27: Jabulusile Shandu | B27: Golf Course Road | C27: EFT | D27: 10 | E27: 083 302 0463 | H27: bavvmilesshandu@gmail.com
A28: Byron Canham | B28: Hillside Road | D28: 10 | E28: 078 610 8996 | H28: byroncanham67@gmail.com
A29: John Carr | B29: Blignaut Street | C29: EFT | D29: 11 | R29: 700 | T29: 350 | V29: 350 | X29: 350 | Z29: 350 | AB29: 350 | AD29: 350 | AF29: 350 | AH29: 350 | AJ29: 350 | AL29: 350 | AO29: 1
A30: VACANT | B30: Hillside Road | D30: 11
A31: Adams | B31: Hugenote Street | D31: 11 | E31: 072 908 9502
A32: Nkosinomusa Mpanza | B32: Blignaut Street | D32: 12 | E32: 083 775 1997 | H32: nkosinomusa.mpanza@gmail.com
A33: Russell Warden | B33: Danie Theron | D33: 12 | E33: 072 264 1626 | H33: russel@basixgroup.co.za
A34: Millicent | B34: Hillside Road | D34: 12 | E34: 060 335 7342 | H34: milly.makoti@yahoo.co.za
A35: Tshepo Makoti | B35: Hillside Road | D35: 12 | E35: 083 490 2586
A36: Jessica | B36: Hillside Road | D36: 12 | E36: 083 764 1855 | H36: sechabadaycare@gmail.com
A37: Lele Pedroncelli | B37: Danie Theron | D37: 13 | E37: 083 286 1327
A38: Fanie | B38: Hugenote Street | D38: 13 | E38: 063 088 3257 | H38: fanie@kieda.co.za
A39: Colin Blandford | B39: Blignaut Street | C39: BLG14 | D39: 14
A40: Patrick Mudhara | B40: Blignaut Street | D40: 14 | E40: 071 550 2414 | H40: patrickmudhara@gmailcom
...

Sheet Bank Reconciliation
A1: MCAA — Bank Reconciliation | Capitec Business 1007012625
A3: March 2026 | 02 March – 31 March 2026
A4: Item | C4: Txns | D4: Amount (R)
A5: INCOME
A6: Membership — Debit Orders | C6: 14 | D6: 19625
A7: Membership — EFT (individual transfers) | C7: 45 | D7: 26750
A8: Camera payments — members | C8: 10 | D8: 11400
A9: Camera payments — sponsors | C9: 5 | D9: 3100
A10: TOTAL INCOME | D10: 60875
A12: EXPENSES
A13: Salary — Mengo Sibanda | C13: 1 | D13: 12500
A14: Maintenance — Fence repair (Luka) | C14: 1 | D14: 3834
A15: Camera purchase — Tary Design | C15: 1 | D15: 14500
A16: Utilities — Water MR SN LANGA (x2) | C16: 2 | D16: 943.02
A17: Other — JLK MCAA | C17: 1 | D17: 4000
A18: Bank fees & DO service charge | C18: 3 | D18: 464.98
A19: Reversals / Unpaid DOs (Weierings) | C19: 2 | D19: 550
A20: TOTAL EXPENSES | D20: 36792
A22: BALANCE CHECK
A23: Opening balance (01 Mar 2026) | D23: 18210.9
A24: + Total money in | D24: 60875
A25: − Total money out | D25: 36792
A26: Calculated closing balance | D26: 42293.9
A27: Actual closing balance (statement) | D27: 42267.9
A28: Difference (should = 0) | D28: -26
A30: Note: R26 difference — minor rounding across DO batch allocations. Under investigation.
A33: April 2026 | 01 April – 30 April 2026
A34: Item | C34: Txns | D34: Amount (R)
A35: INCOME
A36: Membership — Debit Orders (allocated) | C36: 12 | D36: 19625
A37: Membership — EFT (individual transfers) | C37: 18 | D37: 5180
A38: Camera payments — members | C38: 8 | D38: 8850
A39: Camera payments — sponsors | C39: 2 | D39: 1500
A40: DO batch actual received (unallocated R370) | D40: 19995
A41: TOTAL CREDITS | D41: 35525
A43: EXPENSES
A44: Bank fee — DO service charge (01/04) | C44: 1 | D44: 440.61
A45: Other — Red Hot Bit Consultants (02/04) | C45: 1 | D45: 3458
A46: Camera purchase — Tary Design (14/04) | C46: 1 | D46: 14502
A47: Reversal — Weierings Capitec (16/04) | C47: 1 | D47: 170
...

Sheet Bank Statement
A1: MCAA — Bank Statement Register | Capitec Business 1007012625 | Mar–Apr 2026
A2: Month | B2: Date | C2: Reference | D2: Description | E2: Money In (R) | F2: Money Out (R) | G2: Fee (R) | H2: Balance (R) | I2: Category | J2: Matched Member | K2: Address / Plot | L2: D/O Type | M2: Notes
A3: March 2026 | Opening balance: R18,210.90
A4: Mar-26 | B4: 02/03/2026 | C4: MIDVILLECACONTRAEEC0936DA6573E | E4: 11103 | H4: 29313.9 | I4: Membership (DO batch) | J4: (DO batch)
A5: Mar-26 | B5: 02/03/2026 | C5: GOMES 116 DE WET | E5: 300 | H5: 29613.9 | I5: Membership (EFT) | J5: Phil & Chanty Gomes | K5: De Wet Street | Plot 116 | L5: EFT
A6: Mar-26 | B6: 02/03/2026 | C6: G.van Jaarsveld(87 Golf Course | E6: 170 | H6: 29783.9 | I6: Membership (EFT) | J6: Gareth van Jaarsveld | K6: Golf Course Road | Plot 87 | L6: GOL087-EFT
A7: Mar-26 | B7: 02/03/2026 | C7: 62 NICO PELSER STREE | E7: 200 | H7: 29983.9 | I7: Membership (EFT) | J7: Peggy Bennett | K7: Nico Pelser | Plot 62 | L7: EFT
A8: Mar-26 | B8: 02/03/2026 | C8: BLGN11F | E8: 350 | H8: 30333.9 | I8: Membership (EFT) | J8: John Carr | K8: Blignaut Street | Plot 11 | L8: EFT
A9: Mar-26 | B9: 02/03/2026 | C9: 37-1ST AVE WALKERVILLE | E9: 350 | H9: 30683.9 | I9: Membership (EFT) | J9: Peter Kairuz | K9: First Avenue | Plot 37 | L9: EFT
A10: Mar-26 | B10: 02/03/2026 | C10: CAPITEC B MCA1 03-26 | F10: 414.98 | H10: 30268.92 | I10: Bank fee | J10: Bank fee
A11: Mar-26 | B11: 03/03/2026 | C11: MIDVILLECACONTRAEAC49E66A6503A | E11: 800 | H11: 31068.92 | I11: Membership (DO batch) | J11: (DO batch)
A12: Mar-26 | B12: 03/03/2026 | C12: M MUTHALA | E12: 580 | H12: 31648.92 | I12: Membership (EFT) | J12: Gift & Charity Muthala | K12: Road No 7 | Plot 248/1 | L12: EFT
A13: Mar-26 | B13: 03/03/2026 | C13: 153 HOA HLONGWANE | E13: 300 | H13: 31948.92 | I13: Membership (EFT) | J13: Zama and Petunia Hlongwane | K13: Road No 7 | Plot 153 | L13: EFT
A14: Mar-26 | B14: 04/03/2026 | C14: JLK MCAA | F14: 4000 | G14: 6 | H14: 27942.92 | I14: Expense — RTC/other | J14: JLK MCAA
A15: Mar-26 | B15: 04/03/2026 | C15: MR SN LANGA MCAA Water | F15: 471.51 | G15: 1 | H15: 27470.41 | I15: Expense — Water | J15: MR SN LANGA MCAA Water
A16: Mar-26 | B16: 04/03/2026 | C16: M DE VRIES 148/1 | E16: 200 | H16: 27670.41 | I16: Membership (EFT) | J16: Johan and Lelly De Vries (Tennants) | K16: Road No 7 (No Name) | Plot 148/1 | L16: EFT
A17: Mar-26 | B17: 04/03/2026 | C17: 001 UNPAIDS/WEIERINGS CAPITEC | F17: 200 | H17: 27470.41 | I17: Reversal/Unpaid DO | J17: Reversal
A18: Mar-26 | B18: 05/03/2026 | C18: MIDVILLECACONTRAEDC59969A3513F | E18: 200 | H18: 27670.41 | I18: Membership (DO batch) | J18: (DO batch)
A19: Mar-26 | B19: 05/03/2026 | C19: 244RD7HAO-ANDRE | E19: 170 | H19: 27840.41 | I19: Membership (EFT) | J19: Andre De Vries | K19: Road No 7 | Plot 244 | L19: 244RD7HAO
A20: Mar-26 | B20: 05/03/2026 | C20: ABSA BANK 85 Golf Course Road | E20: 170 | H20: 28010.41 | I20: Membership (EFT) | J20: Previn Naidoo | K20: Golf Course Road | Plot 85 | L20: GOL085
A21: Mar-26 | B21: 05/03/2026 | C21: S GROENEWALD | E21: 200 | H21: 28210.41 | I21: Membership (EFT) | J21: Jason and Steven Groenewald | K21: Eeufees Street | Plot 69 | L21: EEU069
A22: Mar-26 | B22: 06/03/2026 | C22: MIDVILLECACONTRAEAC29A68A4503B | E22: 200 | H22: 28410.41 | I22: Membership (DO batch) | J22: (DO batch)
A23: Mar-26 | B23: 09/03/2026 | C23: MIDVILLECACONTRAE5C79F66AA5731 | E23: 363 | H23: 28773.41 | I23: Membership (DO batch) | J23: (DO batch)
A24: Mar-26 | B24: 12/03/2026 | C24: MIDVILLECACONTRAEFC19D69A55F38 | E24: 500 | H24: 29273.41 | I24: Membership (DO batch) | J24: (DO batch)
A25: Mar-26 | B25: 16/03/2026 | C25: MIDVILLECACONTRAEBC7936AAA5F3C | E25: 803 | H25: 30076.41 | I25: Membership (DO batch) | J25: (DO batch)
A26: Mar-26 | B26: 17/03/2026 | C26: MIDVILLECACONTRAEAC19B68A15F3C | E26: 363 | H26: 30439.41 | I26: Membership (DO batch) | J26: (DO batch)
A27: Mar-26 | B27: 18/03/2026 | C27: MIDVILLECACONTRAE4C69B6DA65431 | E27: 300 | H27: 30739.41 | I27: Membership (DO batch) | J27: (DO batch)
A28: Mar-26 | B28: 20/03/2026 | C28: ABSA BANK Plot82Blignautsrus | E28: 350 | H28: 31089.41 | I28: Membership (EFT) | J28: Terry Shapiro | K28: Danie Theron | Plot 82 | L28: ABSA BANK PLOT82BLIGNAUTSRUS
A29: Mar-26 | B29: 23/03/2026 | C29: MIDVILLECACONTRAE9C3986CA0543B | E29: 780 | H29: 31869.41 | I29: Membership (DO batch) | J29: (DO batch)
A30: Mar-26 | B30: 23/03/2026 | C30: 62 NICO PELSER ST. | E30: 3500 | H30: 35369.41 | I30: Membership (EFT) | J30: Peggy Bennett | K30: Nico Pelser | Plot 62 | L30: EFT
A31: Mar-26 | B31: 23/03/2026 | C31: DOLLY CAMERA | E31: 600 | H31: 35969.41 | I31: Camera | J31: Dolly Lolwane (Pride Elephant) | K31: Eloff Street | Plot 57 | L31: BLG057
A32: Mar-26 | B32: 24/03/2026 | C32: Sonya cameras 74 gol | E32: 500 | H32: 36469.41 | I32: Membership (EFT) | J32: Andy and Sonya Delahunty | K32: Golf Course Road | Plot 74 | L32: GOL074
A33: Mar-26 | B33: 24/03/2026 | C33: DAMASKUS PROJECTS | E33: 500 | H33: 36969.41 | I33: Camera (sponsor) | J33: DAMASKUS PROJECTS
A34: Mar-26 | B34: 24/03/2026 | C34: 94 NEL ST /CAMERAS | E34: 500 | H34: 37469.41 | I34: Membership (EFT) | J34: Debbie Rautenbach (Liesl Seymore) | K34: Nel Street | Plot 94 | L34: NEL094
A35: Mar-26 | B35: 24/03/2026 | C35: Bernadette sec camera 38 eloff | E35: 500 | H35: 37969.41 | I35: Camera | J35: Bunty & Lindsay Coryndon-Baker | K35: Eloff Street | Plot 38 | L35: ELO038
A36: Mar-26 | B36: 24/03/2026 | C36: 9 D. Theron; 2026 | E36: 6000 | H36: 43969.41 | I36: Membership (EFT) | J36: Miroslaw Benpkavic | K36: Danie Theron | Plot 9 | L36: ANNUAL EFT
A37: Mar-26 | B37: 24/03/2026 | C37: 9 D. Theron; CAMERA | E37: 3500 | H37: 47469.41 | I37: Camera | J37: Miroslaw Benpkavic | K37: Danie Theron | Plot 9 | L37: ANNUAL EFT
A38: Mar-26 | B38: 24/03/2026 | C38: FIFTH STREET - CAMER | E38: 1000 | H38: 48469.41 | I38: Camera (sponsor) | J38: FIFTH STREET - CAMER
A39: Mar-26 | B39: 25/03/2026 | C39: N SIBEKO | E39: 300 | H39: 48769.41 | I39: Membership (EFT) | J39: Nozisi (Nono) Sibeko & Given Sibeko | K39: Nico Pelser | Plot 58 | L39: NIC058
A40: Mar-26 | B40: 25/03/2026 | C40: MIDVILLECACONTRAE4CF996EAB533A | E40: 700 | H40: 49469.41 | I40: Membership (DO batch) | J40: (DO batch)
...

Sheet Matching Audit Log
A1: Date | B1: Reference | C1: Amount In (R) | D1: Category | E1: Method | F1: Confidence | G1: Matched Member | H1: Row # | I1: Address | J1: Plot | K1: Notes
A2: 02/03/2026 | B2: MIDVILLECACONTRAEEC0936DA6573E | C2: 11103 | D2: Membership (DO batch) | E2: DO_BATCH | F2: HIGH | G2: (DO batch)
A3: 02/03/2026 | B3: GOMES 116 DE WET | C3: 300 | D3: Membership (EFT) | E3: PLOT_STREET | F3: HIGH | G3: Phil & Chanty Gomes | H3: 411 | I3: De Wet Street | J3: 116
A4: 02/03/2026 | B4: G.van Jaarsveld(87 Golf Course | C4: 170 | D4: Membership (EFT) | E4: PLOT_STREET | F4: HIGH | G4: Gareth van Jaarsveld | H4: 341 | I4: Golf Course Road | J4: 87
A5: 02/03/2026 | B5: 62 NICO PELSER STREE | C5: 200 | D5: Membership (EFT) | E5: PLOT_STREET | F5: HIGH | G5: Peggy Bennett | H5: 243 | I5: Nico Pelser | J5: 62
A6: 02/03/2026 | B6: BLGN11F | C6: 350 | D6: Membership (EFT) | E6: MANUAL | F6: HIGH | G6: John Carr | H6: 29 | I6: Blignaut Street | J6: 11 | K6: Matched via Blignaut St plot 11 (John Carr) — D/O ref updated
A7: 02/03/2026 | B7: 37-1ST AVE WALKERVILLE | C7: 350 | D7: Membership (EFT) | E7: MANUAL | F7: HIGH | G7: Peter Kairuz | H7: 106 | I7: First Avenue | J7: 37 | K7: Matched via 1st Ave plot 37 — Peter Kairuz
A8: 03/03/2026 | B8: MIDVILLECACONTRAEAC49E66A6503A | C8: 800 | D8: Membership (DO batch) | E8: DO_BATCH | F8: HIGH | G8: (DO batch)
A9: 03/03/2026 | B9: M MUTHALA | C9: 580 | D9: Membership (EFT) | E9: NAME | F9: HIGH | G9: Gift & Charity Muthala | H9: 494 | I9: Road No 7 | J9: 248/1
A10: 03/03/2026 | B10: 153 HOA HLONGWANE | C10: 300 | D10: Membership (EFT) | E10: PLOT_ONLY | F10: HIGH | G10: Zama and Petunia Hlongwane | H10: 433 | I10: Road No 7 | J10: 153
A11: 04/03/2026 | B11: M DE VRIES 148/1 | C11: 200 | D11: Membership (EFT) | E11: PLOT_ONLY | F11: HIGH | G11: Johan and Lelly De Vries (Tennants) | H11: 485 | I11: Road No 7 (No Name) | J11: 148/1
A12: 05/03/2026 | B12: MIDVILLECACONTRAEDC59969A3513F | C12: 200 | D12: Membership (DO batch) | E12: DO_BATCH | F12: HIGH | G12: (DO batch)
A13: 05/03/2026 | B13: 244RD7HAO-ANDRE | C13: 170 | D13: Membership (EFT) | E13: NAME | F13: HIGH | G13: Andre De Vries | H13: 443 | I13: Road No 7 | J13: 244
A14: 05/03/2026 | B14: ABSA BANK 85 Golf Course Road | C14: 170 | D14: Membership (EFT) | E14: PLOT_STREET | F14: HIGH | G14: Previn Naidoo | H14: 335 | I14: Golf Course Road | J14: 85
A15: 05/03/2026 | B15: S GROENEWALD | C15: 200 | D15: Membership (EFT) | E15: NAME | F15: HIGH | G15: Jason and Steven Groenewald | H15: 268 | I15: Eeufees Street | J15: 69
A16: 06/03/2026 | B16: MIDVILLECACONTRAEAC29A68A4503B | C16: 200 | D16: Membership (DO batch) | E16: DO_BATCH | F16: HIGH | G16: (DO batch)
A17: 09/03/2026 | B17: MIDVILLECACONTRAE5C79F66AA5731 | C17: 363 | D17: Membership (DO batch) | E17: DO_BATCH | F17: HIGH | G17: (DO batch)
A18: 12/03/2026 | B18: MIDVILLECACONTRAEFC19D69A55F38 | C18: 500 | D18: Membership (DO batch) | E18: DO_BATCH | F18: HIGH | G18: (DO batch)
A19: 16/03/2026 | B19: MIDVILLECACONTRAEBC7936AAA5F3C | C19: 803 | D19: Membership (DO batch) | E19: DO_BATCH | F19: HIGH | G19: (DO batch)
A20: 17/03/2026 | B20: MIDVILLECACONTRAEAC19B68A15F3C | C20: 363 | D20: Membership (DO batch) | E20: DO_BATCH | F20: HIGH | G20: (DO batch)
A21: 18/03/2026 | B21: MIDVILLECACONTRAE4C69B6DA65431 | C21: 300 | D21: Membership (DO batch) | E21: DO_BATCH | F21: HIGH | G21: (DO batch)
A22: 20/03/2026 | B22: ABSA BANK Plot82Blignautsrus | C22: 350 | D22: Membership (EFT) | E22: REF_EXACT | F22: HIGH | G22: Terry Shapiro | H22: 323 | I22: Danie Theron | J22: 82
A23: 23/03/2026 | B23: MIDVILLECACONTRAE9C3986CA0543B | C23: 780 | D23: Membership (DO batch) | E23: DO_BATCH | F23: HIGH | G23: (DO batch)
A24: 23/03/2026 | B24: 62 NICO PELSER ST. | C24: 3500 | D24: Membership (EFT) | E24: PLOT_STREET | F24: HIGH | G24: Peggy Bennett | H24: 243 | I24: Nico Pelser | J24: 62
A25: 23/03/2026 | B25: DOLLY CAMERA | C25: 600 | D25: Camera | E25: NAME | F25: HIGH | G25: Dolly Lolwane (Pride Elephant) | H25: 516 | I25: Eloff Street | J25: 57
A26: 24/03/2026 | B26: Sonya cameras 74 gol | C26: 500 | D26: Membership (EFT) | E26: NAME | F26: HIGH | G26: Andy and Sonya Delahunty | H26: 291 | I26: Golf Course Road | J26: 74
A27: 24/03/2026 | B27: DAMASKUS PROJECTS | C27: 500 | D27: Camera (sponsor) | E27: SPONSOR | F27: HIGH | G27: DAMASKUS PROJECTS
A28: 24/03/2026 | B28: 94 NEL ST /CAMERAS | C28: 500 | D28: Membership (EFT) | E28: PLOT_STREET | F28: HIGH | G28: Debbie Rautenbach (Liesl Seymore) | H28: 360 | I28: Nel Street | J28: 94
A29: 24/03/2026 | B29: Bernadette sec camera 38 eloff | C29: 500 | D29: Camera | E29: PLOT_STREET | F29: HIGH | G29: Bunty & Lindsay Coryndon-Baker | H29: 112 | I29: Eloff Street | J29: 38
A30: 24/03/2026 | B30: 9 D. Theron; 2026 | C30: 6000 | D30: Membership (EFT) | E30: PLOT_ONLY | F30: HIGH | G30: Miroslaw Benpkavic | H30: 24 | I30: Danie Theron | J30: 9
A31: 24/03/2026 | B31: 9 D. Theron; CAMERA | C31: 3500 | D31: Camera | E31: PLOT_ONLY | F31: HIGH | G31: Miroslaw Benpkavic | H31: 24 | I31: Danie Theron | J31: 9
A32: 24/03/2026 | B32: FIFTH STREET - CAMER | C32: 1000 | D32: Camera (sponsor) | E32: SPONSOR | F32: HIGH | G32: FIFTH STREET - CAMER
A33: 25/03/2026 | B33: N SIBEKO | C33: 300 | D33: Membership (EFT) | E33: NAME | F33: HIGH | G33: Nozisi (Nono) Sibeko & Given Sibeko | H33: 222 | I33: Nico Pelser | J33: 58
A34: 25/03/2026 | B34: MIDVILLECACONTRAE4CF996EAB533A | C34: 700 | D34: Membership (DO batch) | E34: DO_BATCH | F34: HIGH | G34: (DO batch)
A35: 25/03/2026 | B35: William Cameras | C35: 500 | D35: Membership (EFT) | E35: NAME | F35: HIGH | G35: William Jackson | H35: 515 | I35: Eloff Street | J35: 55
A36: 25/03/2026 | B36: G THIELE | C36: 1500 | D36: Membership (EFT) | E36: NAME | F36: HIGH | G36: Graham Thiele | H36: 329 | I36: Nel Street | J36: 83
A37: 25/03/2026 | B37: Plot 100 Nel cameras | C37: 500 | D37: Camera | E37: REF_EXACT | F37: HIGH | G37: Mbulelo Mbenenge | H37: 379 | I37: Nel Street | J37: 100 | K37: D/O ref "Plot 100 Nel cameras" → Mbulelo Mbenenge (row 379)
A38: 25/03/2026 | B38: P Fourie Cameras | C38: 1000 | D38: Membership (EFT) | E38: NAME | F38: HIGH | G38: Pieter Fourie | H38: 47 | I38: Fifth Street | J38: 19
A39: 25/03/2026 | B39: Nathaniel/78 camera | C39: 2500 | D39: Camera | E39: MANUAL | F39: HIGH | G39: Tracey Van Niekerk | H39: 348 | I39: Nel Street | J39: 90
A40: 25/03/2026 | B40: L CERQUEIRA - CAMERAS | C40: 500 | D40: Membership (EFT) | E40: NAME | F40: HIGH | G40: Lore-lei Cerqueira | H40: 217 | I40: Hillside Road | J40: 57
...

Sheet Expense Register
A1: Date | B1: Reference (bank) | C1: Category | D1: Amount (R) | E1: Notes
A2: 02/03/2026 | B2: CAPITEC B MCA1 03-26 | C2: Bank fee | D2: 414.98 | E2: DO service charge
A3: 04/03/2026 | B3: JLK MCAA | C3: Expense | D3: 4000 | E3: JLK MCAA
A4: 04/03/2026 | B4: MR SN LANGA MCAA Water | C4: Utilities | D4: 471.51 | E4: Water — MR SN LANGA
A5: 04/03/2026 | B5: 001 UNPAIDS/WEIERINGS CAPITEC | C5: Reversal | D5: 200 | E5: Unpaid DO reversal
A6: 27/03/2026 | B6: Mengo Sibanda MCAA | C6: Salary | D6: 12500 | E6: Monthly salary — Mengo Sibanda
A7: 27/03/2026 | B7: LUKA MCAA FENCE | C7: Maintenance | D7: 3834 | E7: Fence repair — Luka
A8: 28/03/2026 | B8: 001 UNPAIDS/WEIERINGS DISC | C8: Reversal | D8: 350 | E8: Unpaid DO reversal
A9: 29/03/2026 | B9: MR SN LANGA MCAA Water | C9: Utilities | D9: 471.51 | E9: Water — MR SN LANGA
A10: 30/03/2026 | B10: TARY DESIGN MCAA | C10: Camera purchase | D10: 14500 | E10: Camera equipment — Tary Design
A11: 31/03/2026 | B11: Month S/Fee | C11: Bank fee | D11: 50 | E11: Monthly account fee
C12: MARCH 2026 TOTAL | D12: 36792
A13: April 2026
A14: 01/04/2026 | B14: CAPITEC B MCA1 04-26 | C14: Bank fee | D14: 440.61 | E14: DO service charge
A15: 02/04/2026 | B15: Red Hot Bit Consultants MCAA | C15: Other | D15: 3458 | E15: Unclassified outgoing — verify with admin
A16: 14/04/2026 | B16: TARY DESIGN MCAA | C16: Camera purchase | D16: 14502 | E16: Camera equipment — Tary Design
A17: 16/04/2026 | B17: 001 UNPAIDS/WEIERINGS CAPITEC | C17: Reversal | D17: 170 | E17: Unpaid DO reversal — R170
A18: 27/04/2026 | B18: Mengo Sibanda MCAA | C18: Salary | D18: 12506 | E18: Monthly salary — Mengo Sibanda
A19: 27/04/2026 | B19: LUKA MCAA FENCE | C19: Maintenance | D19: 4756 | E19: Fence repair — Luka
A20: 29/04/2026 | B20: 001 UNPAIDS/WEIERINGS DISC | C20: Reversal | D20: 350 | E20: Unpaid DO reversal — R350
A21: 30/04/2026 | B21: Month S/Fee | C21: Bank fee | D21: 50 | E21: Monthly account fee
C22: APRIL 2026 TOTAL | D22: 36232.61
A23: May 2026
A24: 02/05/2026 | B24: MR SN LANGA MCAA Water | C24: Utilities | D24: 574 | E24: Water/utilities – MR SN Langa. Incl R1 fee.
A25: 04/05/2026 | B25: CAPITEC B MCA1 05-26 | C25: Bank fee | D25: 462.45 | E25: DO service charge – Capitec
A26: 04/05/2026 | B26: 001 UNPAIDS/WEIERINGS STANDARD | C26: Reversal | D26: 350 | E26: Unpaid DO reversal – R350 (member unknown, bounced at Standard Bank)
A27: 09/05/2026 | B27: TARY DESIGN MCAA | C27: Camera purchase | D27: 16820.06 | E27: Camera equipment – Tary Design. Incl R2 fee.
A28: 09/05/2026 | B28: Reimbursement Nel St Camera refund | C28: Camera refund | D28: 502 | E28: Nel Street camera refund payment. Incl R2 fee.
A29: 16/05/2026 | B29: 001 UNPAIDS/WEIERINGS CAPITEC | C29: Reversal | D29: 170 | E29: EFT reversal – G. van Jaarsveld (87 Golf Course) – Capitec reject
A30: 25/05/2026 | B30: LUKA MCAA FENCE | C30: Maintenance | D30: 4752 | E30: Fence repair – Luka. Incl R2 fee.
A31: 25/05/2026 | B31: Mengo Sibanda MCAA | C31: Salary | D31: 12502 | E31: Monthly salary – Mengo Sibanda. Incl R2 fee.
A32: 29/05/2026 | B32: ATM fees (54 Nico Pelser + NEL ST ANDREW) | C32: Bank fee | D32: 29.54 | E32: ATM cash deposit fees: R22.40 + R7.14
A33: 31/05/2026 | B33: Month S/Fee | C33: Bank fee | D33: 50 | E33: Monthly account fee
C34: MAY 2026 TOTAL | D34: 36212.05
C35: GRAND TOTAL (Mar + Apr + May) | D35: 109236.66

Sheet Payment Summary
B2: MCAA MEMBERSHIP — PAYMENT OVERVIEW
B3: Mar 2025 – May 2026 | Comprehensive List Analysis
B5: MEMBERSHIP SNAPSHOT
B7: Total entries on list | D7: 533
B8: Paying members | D8: 132
B9: Non-paying members | D9: 401
B11: Unique plot numbers | D11: 184
B12: Plots with multiple entries | D12: 118
B14: Total revenue collected (R) | D14: 372684
B16: Payment Rate | D16: 0.25
B17: 401 members have made no payments this year.
B19: MONTHLY COLLECTIONS
B21: Month | C21: Total Collected (R) | D21: # Payers
B22: 46106 | C22: 26778 | D22: 79
B23: 46137 | C23: 25841 | D23: 78
B24: 46167 | C24: 25108 | D24: 74
B25: 46198 | C25: 24028 | D25: 70
B26: 46228 | C26: 30233 | D26: 71
B27: 46259 | C27: 26733 | D27: 68
B28: 46290 | C28: 24183 | D28: 70
B29: 46320 | C29: 21583 | D29: 64
B30: 46351 | C30: 22883 | D30: 66
B31: 46381 | C31: 24233 | D31: 69
B32: 46048 | C32: 32833 | D32: 66
B33: 46079 | C33: 27373 | D33: 75
... B36: 46168 | C36: 29945 | D36: 79
B37: TOTAL

Sheet Members Report
A1: MCAA — MEMBERS PAYMENT DETAIL REPORT
A2: Mar 2025 – Apr 2026 | Rows highlighted in red = zero payments recorded this year
A4: ✅ PAYING MEMBERS
A5: Owner / Tenant | B5: Street / Address | C5: Plot | D5: Total Paid (R) | E5: Source (D/O or EFT)
A6: Paul Gronebaum | B6: Ohenimuri | C6: 8 | D6: 4550
A7: Jason Batalides | B7: Blignaut Street | C7: 1 | D7: 4550
A8: Ian Long | B8: Blignaut Street | C8: 10 | D8: 4550
A9: John Carr | B9: Blignaut Street | C9: 11 | D9: 3500
A10: Evelyn Keartland | B10: De Wet Street | C10: 91 | D10: 5050
A11: Richard & Susan Bentheim | B11: De Wet Street | C11: 93 | D11: 4719
A12: Paul & Liz Lottreaux (Celtic Software) | B12: De Wet Street | C12: 101 | D12: 4550
A13: Aaqil Pariachi | B13: De Wet Street | C13: 104 | D13: 350
A14: Nazam | B14: De Wet Street | C14: 108 | D14: 850
A15: Sifiso Masango / Tumiso | B15: De Wet Street | C15: 110 | D15: 1000
A16: Phil & Chanty Gomes | B16: De Wet Street | C16: 116 | D16: 3600
A17: Rachel Balthazar | B17: Road No 8 | C17: 143 | D17: 1200
... A35: Janos Herceg | B35: Centre Road | C35: 51 | D35: 4550
A36: Millicent Nkosi | B36: Centre Road | C36: 54-1 | D36: 200
A37: No reference | B37: Fifth Street | C37: ? | D37: 500
A38: Pieter Fourie | B38: Fifth Street | C38: 19 | D38: 5550
A39: Andrew & Robyn Weeks | B39: Fifth Street | C39: 20 | D39: 4550
A40: Alan & Louise Proudfoot | B40: Fifth Street | C40: 25 | D40: 5005
A41: Eschelle Wathen | B41: Fifth Street | C41: 53 | D41: 4550
A42: Cindy Wills | B42: Fifth Street | C42: 59 | D42: 5720
A43: Basil | B43: Fifth Street | C43: 61 | D43: 6750
A44: Miroslaw Benpkavic | B44: Danie Theron | C44: 9 | D44: 15500
A45: Heinrich Hendrikz | B45: Danie Theron | C45: 10 | D45: 500
A46: Andre Brummer | B46: Danie Theron | C46: 81 | D46: 3000
A47: Terry Shapiro | B47: Danie Theron | C47: 82 | D47: 5050
A48: Thulani Timile | B48: Danie Theron | C48: 117 | D48: 1200
A49: Gerald Bezuidenhout (Fuel Trailers) | B49: First Avenue | C49: 1,3,7 | D49: 350
A50: Lesley Visser | B50: First Avenue | C50: 9 | D50: 4550
A51: Abbeyfield | B51: First Avenue | C51: 16 | D51: 4550
A52: Wayne Pettit | B52: First Avenue | C52: 17 | D52: 4719
A53: Carien Abrahams | B53: First Avenue | C53: 22 | D53: 4550
A54: May Lyna/ Judith | B54: First Avenue | C54: 25 | D54: 1050
A55: Peter Kairuz | B55: First Avenue | C55: 37 | D55: 5050
A56: Jose Pinto | B56: First Avenue | C56: 39 | D56: 4550
A57: Steve Messenger/Juanita | B57: First Avenue | C57: 41 | D57: 4000
A58: Shaun Traut | B58: First Avenue | C58: 43 | D58: 5050
...

Sheet Street Captains
A1: MCAA Street Captains
A2: Blignaut Street | E2: 4 of 8
A3: De Wet Street | B3: Richard Bentheim | C3: richieinza@gmail.com | D3: 084 304 1478 | E3: 7 of 17
A4: Eloff Street | E4: 7 of 19
A5: Road No 8 | E5: 1 of 5
A6: Eufees Street | B6: Rolf | C6: rolfhanswillenbrock@gmail.com | D6: 083 463 6402 | E6: 2 of 11
A7: Fifth Street | B7: Thulani Timile | C7: sabdmc@mail.com | D7: 083 959 2854 | E7: 5 of 21
A8: First Avenue | E8: 9 of 30
A9: Golf Course Road | B9: Kevin | C9: kevin@camerapress.co.za | D9: 082 490 8066 | E9: 9 of 26
A10: Green/Angle Road | B10: Mark Thompson | C10: markthompson.mt941@gmail.com | D10: 083 260 9080 | E10: 4 of 14
A11: Hillside Road | B11: James Owens | C11: Jamesaowens@gmail.com | D11: 0836557792 | E11: 5 of 27
A12: Hugenote Street | E12: 0 of 12
A13: Nel Street | B13: Cliff Webb | C13: cliff@paradigmprint.co.za | D13: 082 571 5142 | E13: 4 of 16
A14: Nico Pelser/Fourth St. | B14: Paul Lottreaux | C14: Lottreauxpaul@gmail.com | D14: 081 098 3664 | E14: 3 of 26
A15: Orchard Road | B15: Anton | C15: anton@abceramics.co.za | D15: 078 925 3151 | E15: 1 of 19
A16: Third Ave. | B16: Chris Leeson | C16: Chris@cai.co.za | D16: 083 600 0450 | E16: 1 of 14
A17: Second Avenue | E17: 2 of 18
A18: Road No 7 | B18: Zama Hlongwane | C18: zamohr@gmail.com | D18: 083 265 1152 | E18: 3 of 17
A19: Voortrekker Street | E19: 1 of 13

Sheet Blignautsrus North
A1: Owner / Tenant | B1: Address | C1: D/O Ref | D1: Plot | E1: Contact 1 | F1: Contact 2 | G1: Contact 3 | H1: E-mail address | I1: Comments Sep | J1: Jan-25 DO | K1: Jan-25 EFT | L1: Feb-25 DO | M1: Feb-25 EFT | N1: Mar-25 DO | O1: Mar-25 EFT | P1: Apr-25 DO | Q1: Apr-25 EFT | R1: May-25 DO | S1: May-25 EFT | T1: Jun-25 DO | U1: Jun-25 EFT | V1: Jul-25 DO | W1: Jul-25 EFT | X1: Aug-25 DO | Y1: Aug-25 EFT | Z1: Sep-25 DO | AA1: Sep-25 EFT | AB1: Oct-25 DO | AC1: Oct-25 EFT | AD1: Nov-25 DO | AE1: Nov-25 EFT | AF1: Dec-25 DO | AG1: Dec-25 EFT | AH1: Jan-26 DO | AI1: Jan-26 EFT | AJ1: Feb-26 DO | AK1: Feb-26 EFT | AL1: Mar-26 DO | AM1: Mar-26 EFT | AN1: Comments
A2: Jason Batalides | B2: Blignaut Street | C2: HZB038 | D2: 1 | E2: 082 557 1110 | F2: 0614960119 | J2: 350 | L2: 350 | N2: 350 | P2: 350 | R2: 350 | T2: 350 | V2: 350 | X2: 350 | Z2: 350 | AB2: 350 | AD2: 350 | AF2: 350 | AH2: 350 | AJ2: 350 | AL2: 350 | AN2: HZB038 = D/O ref
B3: Blignaut Street | D3: 4
B4: Blignaut Street | D4: 6
A5: Desire (Girls on the Move) | B5: Blignaut Street | D5: 8 | AN5: Wants to start paying end Jan
A6: Anthony Byrne | B6: Blignaut Street | C6: BLG08A | D6: 8a
A7: Ian Long | B7: Blignaut Street | C7: BLG010 | D7: 10 | J7: 350 | L7: 350 | N7: 350 | P7: 350 | R7: 350 | T7: 350 | V7: 350 | X7: 350 | Z7: 350 | AB7: 350 | AD7: 350 | AF7: 350 | AH7: 350 | AJ7: 350 | AL7: 350
A8: John Carr | B8: Blignaut Street | C8: EFT | D8: 11 | W8: 700 | Y8: 350 | AA8: 350 | AC8: 350 | AE8: 350 | AG8: 350 | AI8: 350 | AK8: 350 | AM8: 350 | AN8: New Jul25
B9: Blignaut Street | D9: 12
A10: Colin Blandford | B10: Blignaut Street | C10: BLG14 | D10: 14
B11: Blignaut Street | D11: 16
A14: Greg Stevens | B14: Eeufees Street | D14: 3 | E14: 082 466 6457
A17: Gerald Bezuidenhout (Fuel Trailers) | B17: First Avenue | C17: 1ST001 | D17: 1 | E17: 011 730 8031
A18: Lesley Visser | B18: First Avenue | C18: 1ST009 | D18: 9b | E18: 083 469 7838 | H18: midvaalward7@gmail.com | J18: 350 | L18: 350 | N18: 350 | P18: 350 | R18: 350 | T18: 350 | V18: 350 | X18: 350 | Z18: 350 | AB18: 350 | AD18: 350 | AF18: 350 | AH18: 350 | AJ18: 350 | AL18: 350
B19: First Avenue | D19: 11
B20: First Avenue | D20: 13
A21: Alistair Leukes | B21: First Avenue | D21: 15 | E21: 061 467 8440 | H21: alistair@amlsol.com
A22: Abbeyfield | B22: First Avenue | C22: BLG 016 | D22: 16 | J22: 350 | L22: 350 | N22: 350 | P22: 350 | R22: 350 | T22: 350 | V22: 350 | X22: 350 | Z22: 350 | AB22: 350 | AD22: 350 | AF22: 350 | AH22: 350 | AJ22: 350 | AL22: 350
A23: Wayne Pettit | B23: First Avenue | C23: BLG 017 | D23: 17 | J23: 363 | L23: 363 | N23: 363 | P23: 363 | R23: 363 | T23: 363 | V23: 363 | X23: 363 | Z23: 363 | AB23: 363 | AD23: 363 | AF23: 363 | AH23: 363 | AJ23: 363 | AL23: 363
B26: Hugenote Street | D26: 3
B27: Hugenote Street | D27: 5
A28: Eugene | B28: Hugenote Street | D28: 7 | E28: 076 440 9248
B29: Hugenote Street | D29: 9
A30: Adams | B30: Hugenote Street | D30: 11 | E30: 072 908 9502
A31: Fanie | B31: Hugenote Street | D31: 13 | E31: 063 088 3257 | H31: fanie@kieda.co.za
A32: Ncedo Vilikati | B32: Hugenote Street | D32: 15 | E32: 079 707 1993
B33: Hugenote Street | D33: 17
A34: Karel | B34: Hugenote Street | D34: 18 | E34: 082 308 1525 | H34: karel@kfb.co.za
A35: Minnie | B35: Hugenote Street | D35: 20 | E35: 082 796 7074 | H35: tinus@kwn.co.za
A36: Sandile Mbanjwa | B36: Hugenote Street | D36: 22 | AI36: 4200 | AN36: Annual payment 16/01/26
A37: K. Aboobaker | B37: Hugenote Street | D37: 24 | E37: 081 385 5048 | H37: mentorconch11@gmail.com
B40: Voortrekker St. | D40: 19
B41: Voortrekker St. | D41: 21
B42: Voortrekker St. | D42: 23
B43: Voortrekker St. | D43: 25
B44: Voortrekker St. | D44: 26
B45: Voortrekker St. | D45: 27
B46: Voortrekker St. | D46: 29
B47: Voortrekker St. | D47: 31
B48: Voortrekker St. | D48: 35
...

Sheet Notes
A1: Sample of how to load on old Mercantile system - see below snip | I1: Capitec supp | J1: 021 137 6818
A2: Print financial reports which has all info including unpaid debit orders for recon
A3: User Paul - MCA1 - Sharon**9
A5: https://ebureau.mercantile.co.za/meb3/online/
